Traceback (most recent call last):
  File "/home/runner/miniconda3/envs/guides/lib/python3.10/site-packages/jupyter_cache/executors/utils.py", line 58, in single_nb_execution
    executenb(
  File "/home/runner/miniconda3/envs/guides/lib/python3.10/site-packages/nbclient/client.py", line 1314, in execute
    return NotebookClient(nb=nb, resources=resources, km=km, **kwargs).execute()
  File "/home/runner/miniconda3/envs/guides/lib/python3.10/site-packages/jupyter_core/utils/__init__.py", line 165, in wrapped
    return loop.run_until_complete(inner)
  File "/home/runner/miniconda3/envs/guides/lib/python3.10/asyncio/base_events.py", line 649, in run_until_complete
    return future.result()
  File "/home/runner/miniconda3/envs/guides/lib/python3.10/site-packages/nbclient/client.py", line 709, in async_execute
    await self.async_execute_cell(
  File "/home/runner/miniconda3/envs/guides/lib/python3.10/site-packages/nbclient/client.py", line 1062, in async_execute_cell
    await self._check_raise_for_error(cell, cell_index, exec_reply)
  File "/home/runner/miniconda3/envs/guides/lib/python3.10/site-packages/nbclient/client.py", line 918, in _check_raise_for_error
    raise CellExecutionError.from_cell_and_msg(cell, exec_reply_content)
nbclient.exceptions.CellExecutionError: An error occurred while executing the following cell:
------------------
# this will result in an error
np.array(1, 2, 3)
------------------


[0;31m---------------------------------------------------------------------------[0m
[0;31mTypeError[0m                                 Traceback (most recent call last)
Cell [0;32mIn[5], line 2[0m
[1;32m      1[0m [38;5;66;03m# this will result in an error[39;00m
[0;32m----> 2[0m [43mnp[49m[38;5;241;43m.[39;49m[43marray[49m[43m([49m[38;5;241;43m1[39;49m[43m,[49m[43m [49m[38;5;241;43m2[39;49m[43m,[49m[43m [49m[38;5;241;43m3[39;49m[43m)[49m

[0;31mTypeError[0m: array() takes from 1 to 2 positional arguments but 3 were given

