Traceback (most recent call last):
  File "/home/runner/miniconda3/envs/guides/lib/python3.10/site-packages/jupyter_cache/executors/utils.py", line 58, in single_nb_execution
    executenb(
  File "/home/runner/miniconda3/envs/guides/lib/python3.10/site-packages/nbclient/client.py", line 1314, in execute
    return NotebookClient(nb=nb, resources=resources, km=km, **kwargs).execute()
  File "/home/runner/miniconda3/envs/guides/lib/python3.10/site-packages/jupyter_core/utils/__init__.py", line 165, in wrapped
    return loop.run_until_complete(inner)
  File "/home/runner/miniconda3/envs/guides/lib/python3.10/asyncio/base_events.py", line 649, in run_until_complete
    return future.result()
  File "/home/runner/miniconda3/envs/guides/lib/python3.10/site-packages/nbclient/client.py", line 709, in async_execute
    await self.async_execute_cell(
  File "/home/runner/miniconda3/envs/guides/lib/python3.10/site-packages/nbclient/client.py", line 1062, in async_execute_cell
    await self._check_raise_for_error(cell, cell_index, exec_reply)
  File "/home/runner/miniconda3/envs/guides/lib/python3.10/site-packages/nbclient/client.py", line 918, in _check_raise_for_error
    raise CellExecutionError.from_cell_and_msg(cell, exec_reply_content)
nbclient.exceptions.CellExecutionError: An error occurred while executing the following cell:
------------------
abline(reg = lm(formula = Maximum.Wind ~ Year, data = hurrdata2),
       col = "red",     # line color
       lty = "dashed",  # line type
       lwd = 3)         # line width
------------------


Error in int_abline(a = a, b = b, h = h, v = v, untf = untf, ...): plot.new has not been called yet
Traceback:

1. abline(reg = lm(formula = Maximum.Wind ~ Year, data = hurrdata2), 
 .     col = "red", lty = "dashed", lwd = 3)
2. int_abline(a = a, b = b, h = h, v = v, untf = untf, ...)

